const catchAsyncError = (req, res, next) => {

}